Workbook

Sheet Como usar
A1: Gabarito do corpus de avaliação — rascunho para revisão
A3: O que é | B3: Afirmações centrais de cada um dos 11 documentos (8 artigos da dissertação + 3 de aviônica), parafraseadas em português, com a página de onde vêm. É a referência contra a qual os fichamentos do agente serão medidos (precisão de citação, afirmações sem suporte, cobertura).
A4: Origem | B4: Rascunho gerado por Claude a partir do texto dos PDFs. Os termos-chave e números de cada afirmação foram conferidos automaticamente contra o texto da página citada (77 de 77 encontrados), mas a escolha do que é 'central' e a paráfrase precisam da sua revisão.
A5: Convenção de página | B5: Página física do PDF: 1 = primeira página do arquivo. NÃO é a numeração impressa do periódico (ex.: IEEE Access imprime 70061 na p. 1). O agente deve citar na mesma convenção.
A6: O que você preenche | B6: Só as colunas amarelas da aba Gabarito: 'Status' (lista: Aprovada, Corrigir, Rejeitar) e 'Correção / comentário'. Se mudar a página inicial, a coluna 'Posição' se recalcula.
A7: Exemplo de preenchimento | B7: Status = Corrigir · Correção / comentário = 'A página certa é 9, não 8' — ou Status = Rejeitar · 'Não é central; trocar pela afirmação sobre X (p. 5)'.
A8: Posição no texto | B8: início / meio / fim, pela página inicial em relação ao total de páginas (terços). Serve para testar o efeito 'lost in the middle' (Liu et al., 2023): o agente erra mais no meio de textos longos?
A9: Observações | B9: Divergências internas dos próprios artigos (ex.: 3,5 W no resumo vs 3,6 W nos resultados) e armadilhas para o agente estão anotadas. São bons casos de teste.
A11: Progresso da revisão
A12: Total de afirmações | B12: =COUNTA(Gabarito!A2:A1000) -> 109
A13: Aprovadas | B13: =COUNTIF(Gabarito!I2:I1000,"Aprovada") -> 0
A14: A corrigir | B14: =COUNTIF(Gabarito!I2:I1000,"Corrigir") -> 0
A15: Rejeitadas | B15: =COUNTIF(Gabarito!I2:I1000,"Rejeitar") -> 0
A16: Ainda sem revisão | B16: =B12-B13-B14-B15 -> 109

Sheet Gabarito
A1: ID | B1: Artigo | C1: Referência | D1: Tipo | E1: Afirmação (paráfrase) | F1: Página(s) no PDF | G1: Pág. inicial | H1: Posição | I1: Status | J1: Correção / comentário | K1: Observação
A2: A1-01 | B2: 1 | C2: Nimbekar et al., 2023 | D2: Contribuição | E2: Propõe uma arquitetura VLSI reconfigurável e de baixa complexidade que executa duas redes de deep learning para reconhecimento de gestos em reabilitação: LoCoMo-Net (membro superior) e MyoNet (membro inferior). | F2: p. 1 | G2: 1 | H2: =IF(G2/INDEX(Artigos!$G$2:$G$12,MATCH(B2,Artigos!$A$2:$A$12,0))<=1/3,"início",IF(G2/INDEX(Artigos!$G$2:$G$12,MATCH(B2,Artigos!$A$2:$A$12,0))<=2/3,"meio","fim")) -> início | K2: Na conclusão (p. 8) os membros aparecem trocados ('hindlimb (upper limb)', 'forelimb (lower limb)'), contrariando a introdução (p. 1).
A3: A1-02 | B3: 1 | C3: Nimbekar et al., 2023 | D3: Método | E3: O projeto foi implementado no FPGA Zynq UltraScale+ MPSoC ZCU102. | F3: p. 1 | G3: 1 | H3: =IF(G3/INDEX(Artigos!$G$2:$G$12,MATCH(B3,Artigos!$A$2:$A$12,0))<=1/3,"início",IF(G3/INDEX(Artigos!$G$2:$G$12,MATCH(B3,Artigos!$A$2:$A$12,0))<=2/3,"meio","fim")) -> início
A4: A1-03 | B4: 1 | C4: Nimbekar et al., 2023 | D4: Método | E4: As operações comuns às duas redes (convolução, ReLU e max-pooling) ficam na lógica programável; as que variam (LSTM e camada totalmente conectada) rodam no processador. | F4: p. 5 | G4: 5 | H4: =IF(G4/INDEX(Artigos!$G$2:$G$12,MATCH(B4,Artigos!$A$2:$A$12,0))<=1/3,"início",IF(G4/INDEX(Artigos!$G$2:$G$12,MATCH(B4,Artigos!$A$2:$A$12,0))<=2/3,"meio","fim")) -> meio
A5: A1-04 | B5: 1 | C5: Nimbekar et al., 2023 | D5: Método | E5: Todas as operações usam ponto flutuante de 16 bits; a memória DDR é a principal e as BRAMs guardam resultados intermediários. | F5: p. 5 | G5: 5 | H5: =IF(G5/INDEX(Artigos!$G$2:$G$12,MATCH(B5,Artigos!$A$2:$A$12,0))<=1/3,"início",IF(G5/INDEX(Artigos!$G$2:$G$12,MATCH(B5,Artigos!$A$2:$A$12,0))<=2/3,"meio","fim")) -> meio
A6: A1-05 | B6: 1 | C6: Nimbekar et al., 2023 | D6: Resultado | E6: Não há perda de acurácia ao executar as redes em CPU, GPU e FPGA. | F6: p. 6 | G6: 6 | H6: =IF(G6/INDEX(Artigos!$G$2:$G$12,MATCH(B6,Artigos!$A$2:$A$12,0))<=1/3,"início",IF(G6/INDEX(Artigos!$G$2:$G$12,MATCH(B6,Artigos!$A$2:$A$12,0))<=2/3,"meio","fim")) -> meio
A7: A1-06 | B7: 1 | C7: Nimbekar et al., 2023 | D7: Resultado | E7: O tempo de reconhecimento no FPGA é 1,876 ms (LoCoMo-Net) e 61,988 ms (MyoNet), abaixo do limite de 300 ms para controle protético em tempo real. | F7: p. 7 | G7: 7 | H7: =IF(G7/INDEX(Artigos!$G$2:$G$12,MATCH(B7,Artigos!$A$2:$A$12,0))<=1/3,"início",IF(G7/INDEX(Artigos!$G$2:$G$12,MATCH(B7,Artigos!$A$2:$A$12,0))<=2/3,"meio","fim")) -> fim | K7: Na mesma página o tempo da LoCoMo-Net aparece também como 1,879 ms.
A8: A1-07 | B8: 1 | C8: Nimbekar et al., 2023 | D8: Resultado | E8: A potência no FPGA é 3,6 W (LoCoMo-Net) e 5 W (MyoNet), contra 16 W e 23 W na GPU Jetson TX2, ou seja, 4 a 4,6 vezes menor. | F8: p. 7 | G8: 7 | H8: =IF(G8/INDEX(Artigos!$G$2:$G$12,MATCH(B8,Artigos!$A$2:$A$12,0))<=1/3,"início",IF(G8/INDEX(Artigos!$G$2:$G$12,MATCH(B8,Artigos!$A$2:$A$12,0))<=2/3,"meio","fim")) -> fim | K8: Divergência interna: o resumo (p. 1) informa 3,5 W para a LoCoMo-Net no FPGA.
A9: A1-08 | B9: 1 | C9: Nimbekar et al., 2023 | D9: Resultado | E9: A síntese em tecnologia GF 40 nm ocupa 2,046 mm² e consome 300,8423 mW a 1,21 V. | F9: p. 1; 7 | G9: 1 | H9: =IF(G9/INDEX(Artigos!$G$2:$G$12,MATCH(B9,Artigos!$A$2:$A$12,0))<=1/3,"início",IF(G9/INDEX(Artigos!$G$2:$G$12,MATCH(B9,Artigos!$A$2:$A$12,0))<=2/3,"meio","fim")) -> início
A10: A1-09 | B10: 1 | C10: Nimbekar et al., 2023 | D10: Resultado | E10: A energia gasta pela LoCoMo-Net é 1440 J na GPU, 0,67 J no FPGA e 0,0045 J no ASIC. | F10: p. 7 | G10: 7 | H10: =IF(G10/INDEX(Artigos!$G$2:$G$12,MATCH(B10,Artigos!$A$2:$A$12,0))<=1/3,"início",IF(G10/INDEX(Artigos!$G$2:$G$12,MATCH(B10,Artigos!$A$2:$A$12,0))<=2/3,"meio","fim")) -> fim | K10: Números incomuns (90 s na GPU); bom teste para ver se o agente copia sem 'corrigir'.
A11: A1-10 | B11: 1 | C11: Nimbekar et al., 2023 | D11: Conclusão | E11: O projeto usa menos de 20% dos recursos totais do FPGA. | F11: p. 8 | G11: 8 | H11: =IF(G11/INDEX(Artigos!$G$2:$G$12,MATCH(B11,Artigos!$A$2:$A$12,0))<=1/3,"início",IF(G11/INDEX(Artigos!$G$2:$G$12,MATCH(B11,Artigos!$A$2:$A$12,0))<=2/3,"meio","fim")) -> fim
A12: A2-01 | B12: 2 | C12: Breyer et al., 2022 | D12: Contribuição | E12: Compara OpenMP, CUDA, OpenCL e SYCL (implementações hipSYCL e DPC++) quanto a usabilidade, desempenho e portabilidade de desempenho, em GPUs NVIDIA, AMD e Intel e CPUs AMD e Intel. | F12: p. 1 | G12: 1 | H12: =IF(G12/INDEX(Artigos!$G$2:$G$12,MATCH(B12,Artigos!$A$2:$A$12,0))<=1/3,"início",IF(G12/INDEX(Artigos!$G$2:$G$12,MATCH(B12,Artigos!$A$2:$A$12,0))<=2/3,"meio","fim")) -> início
A13: A2-02 | B13: 2 | C13: Breyer et al., 2022 | D13: Método | E13: A carga de trabalho é a biblioteca PLSSVM (LS-SVM), cuja parte mais custosa é resolver um sistema linear pelo método do Gradiente Conjugado. | F13: p. 1 | G13: 1 | H13: =IF(G13/INDEX(Artigos!$G$2:$G$12,MATCH(B13,Artigos!$A$2:$A$12,0))<=1/3,"início",IF(G13/INDEX(Artigos!$G$2:$G$12,MATCH(B13,Artigos!$A$2:$A$12,0))<=2/3,"meio","fim")) -> início
A14: A2-03 | B14: 2 | C14: Breyer et al., 2022 | D14: Resultado | E14: Resolver o sistema linear (CG) domina o tempo de execução; as demais partes ocupam no máximo 3,8% do tempo. | F14: p. 5 | G14: 5 | H14: =IF(G14/INDEX(Artigos!$G$2:$G$12,MATCH(B14,Artigos!$A$2:$A$12,0))<=1/3,"início",IF(G14/INDEX(Artigos!$G$2:$G$12,MATCH(B14,Artigos!$A$2:$A$12,0))<=2/3,"meio","fim")) -> meio
A15: A2-04 | B15: 2 | C15: Breyer et al., 2022 | D15: Método | E15: O OpenCL compila os kernels por JIT em tempo de execução, com overhead entre cerca de cem milissegundos e mais de dois minutos. | F15: p. 4 | G15: 4 | H15: =IF(G15/INDEX(Artigos!$G$2:$G$12,MATCH(B15,Artigos!$A$2:$A$12,0))<=1/3,"início",IF(G15/INDEX(Artigos!$G$2:$G$12,MATCH(B15,Artigos!$A$2:$A$12,0))<=2/3,"meio","fim")) -> início
A16: A2-05 | B16: 2 | C16: Breyer et al., 2022 | D16: Resultado | E16: Na P100 com 2^15 pontos, o CUDA leva 1,6 s por iteração do CG e o OpenCL 1,7 s; hipSYCL (3,8 s) e DPC++ (7,2 s) são 2,3× e 4,5× mais lentos que o CUDA. | F16: p. 8 | G16: 8 | H16: =IF(G16/INDEX(Artigos!$G$2:$G$12,MATCH(B16,Artigos!$A$2:$A$12,0))<=1/3,"início",IF(G16/INDEX(Artigos!$G$2:$G$12,MATCH(B16,Artigos!$A$2:$A$12,0))<=2/3,"meio","fim")) -> meio
A17: A2-06 | B17: 2 | C17: Breyer et al., 2022 | D17: Resultado | E17: Um bug do DPC++ impede o inlining do atomic add; removendo-o, o tempo cai 38% (de 7,2 s para 4,5 s). | F17: p. 8 | G17: 8 | H17: =IF(G17/INDEX(Artigos!$G$2:$G$12,MATCH(B17,Artigos!$A$2:$A$12,0))<=1/3,"início",IF(G17/INDEX(Artigos!$G$2:$G$12,MATCH(B17,Artigos!$A$2:$A$12,0))<=2/3,"meio","fim")) -> meio
A18: A2-07 | B18: 2 | C18: Breyer et al., 2022 | D18: Resultado | E18: Na GPU AMD Radeon Pro VII os backends rendem menos que nas NVIDIA (9,9 s contra 6,7 s na P100), o que os autores atribuem ao ajuste de blocos feito para GPU NVIDIA: portabilidade de desempenho exige ajuste fino. | F18: p. 8 | G18: 8 | H18: =IF(G18/INDEX(Artigos!$G$2:$G$12,MATCH(B18,Artigos!$A$2:$A$12,0))<=1/3,"início",IF(G18/INDEX(Artigos!$G$2:$G$12,MATCH(B18,Artigos!$A$2:$A$12,0))<=2/3,"meio","fim")) -> meio
A19: A2-08 | B19: 2 | C19: Breyer et al., 2022 | D19: Resultado | E19: Em CPUs, o kernel hierárquico do hipSYCL é em média 24× mais rápido que o nd_range (mín. 4,3; máx. 118,4), mas obriga a manter duas versões do mesmo código. | F19: p. 9 | G19: 9 | H19: =IF(G19/INDEX(Artigos!$G$2:$G$12,MATCH(B19,Artigos!$A$2:$A$12,0))<=1/3,"início",IF(G19/INDEX(Artigos!$G$2:$G$12,MATCH(B19,Artigos!$A$2:$A$12,0))<=2/3,"meio","fim")) -> fim
A20: A2-09 | B20: 2 | C20: Breyer et al., 2022 | D20: Conclusão | E20: Nenhum backend é o mais rápido em todo hardware: CUDA vence nas GPUs NVIDIA, OpenCL nas GPUs AMD e Intel, e DPC++ nas CPUs onde pôde ser usado. | F20: p. 11 | G20: 11 | H20: =IF(G20/INDEX(Artigos!$G$2:$G$12,MATCH(B20,Artigos!$A$2:$A$12,0))<=1/3,"início",IF(G20/INDEX(Artigos!$G$2:$G$12,MATCH(B20,Artigos!$A$2:$A$12,0))<=2/3,"meio","fim")) -> fim
A21: A2-10 | B21: 2 | C21: Breyer et al., 2022 | D21: Conclusão | E21: Recomendam CUDA se só GPUs NVIDIA forem alvo, OpenMP se só CPUs, e SYCL para uso geral, mesmo que o OpenCL seja frequentemente mais rápido. | F21: p. 11–12 | G21: 11 | H21: =IF(G21/INDEX(Artigos!$G$2:$G$12,MATCH(B21,Artigos!$A$2:$A$12,0))<=1/3,"início",IF(G21/INDEX(Artigos!$G$2:$G$12,MATCH(B21,Artigos!$A$2:$A$12,0))<=2/3,"meio","fim")) -> fim | K21: Afirmação que atravessa a quebra de página.
A22: A3-01 | B22: 3 | C22: Sifakis, 2015 | D22: Contribuição | E22: O sucesso da automação de projeto eletrônico (EDA) se apoia em quatro princípios: separação de interesses, projeto baseado em componentes, coerência semântica e correção por construção. | F22: p. 1 | G22: 1 | H22: =IF(G22/INDEX(Artigos!$G$2:$G$12,MATCH(B22,Artigos!$A$2:$A$12,0))<=1/3,"início",IF(G22/INDEX(Artigos!$G$2:$G$12,MATCH(B22,Artigos!$A$2:$A$12,0))<=2/3,"meio","fim")) -> início
A23: A3-02 | B23: 3 | C23: Sifakis, 2015 | D23: Contribuição | E23: O artigo discute até que ponto o paradigma da EDA pode ser adaptado ao projeto de sistemas mistos hardware/software. | F23: p. 1 | G23: 1 | H23: =IF(G23/INDEX(Artigos!$G$2:$G$12,MATCH(B23,Artigos!$A$2:$A$12,0))<=1/3,"início",IF(G23/INDEX(Artigos!$G$2:$G$12,MATCH(B23,Artigos!$A$2:$A$12,0))<=2/3,"meio","fim")) -> início
A24: A3-03 | B24: 3 | C24: Sifakis, 2015 | D24: Contexto | E24: Três obstáculos: falta de métodos rigorosos para especificar requisitos; intratabilidade de síntese e verificação para software com número potencialmente infinito de estados; dificuldade de prever o comportamento do software sobre o hardware. | F24: p. 2 | G24: 2 | H24: =IF(G24/INDEX(Artigos!$G$2:$G$12,MATCH(B24,Artigos!$A$2:$A$12,0))<=1/3,"início",IF(G24/INDEX(Artigos!$G$2:$G$12,MATCH(B24,Artigos!$A$2:$A$12,0))<=2/3,"meio","fim")) -> início
A25: A3-04 | B25: 3 | C25: Sifakis, 2015 | D25: Conceito | E25: Correção de sistema combina confiabilidade (trustworthiness: nada de ruim acontece) e otimização (desempenho, custo-efetividade e compromissos entre eles). | F25: p. 2 | G25: 2 | H25: =IF(G25/INDEX(Artigos!$G$2:$G$12,MATCH(B25,Artigos!$A$2:$A$12,0))<=1/3,"início",IF(G25/INDEX(Artigos!$G$2:$G$12,MATCH(B25,Artigos!$A$2:$A$12,0))<=2/3,"meio","fim")) -> início
A26: A3-05 | B26: 3 | C26: Sifakis, 2015 | D26: Argumento | E26: Confiabilidade e otimização são difíceis de conciliar: aumentar a confiabilidade costuma gastar mais recursos, e otimizar recursos pode comprometer a confiabilidade. | F26: p. 3 | G26: 3 | H26: =IF(G26/INDEX(Artigos!$G$2:$G$12,MATCH(B26,Artigos!$A$2:$A$12,0))<=1/3,"início",IF(G26/INDEX(Artigos!$G$2:$G$12,MATCH(B26,Artigos!$A$2:$A$12,0))<=2/3,"meio","fim")) -> início
A27: A3-06 | B27: 3 | C27: Sifakis, 2015 | D27: Proposta | E27: Defende deslocar o foco dos métodos formais para o projeto rigoroso de sistemas, com ênfase em correção por construção. | F27: p. 3 | G27: 3 | H27: =IF(G27/INDEX(Artigos!$G$2:$G$12,MATCH(B27,Artigos!$A$2:$A$12,0))<=1/3,"início",IF(G27/INDEX(Artigos!$G$2:$G$12,MATCH(B27,Artigos!$A$2:$A$12,0))<=2/3,"meio","fim")) -> início
A28: A3-07 | B28: 3 | C28: Sifakis, 2015 | D28: Conceito | E28: Responsabilização (accountability): o projetista mostra evidências de que suas escolhas atendem aos requisitos e garante que propriedades já estabelecidas continuam valendo nas etapas seguintes; assurance cases ajudam nisso. | F28: p. 4 | G28: 4 | H28: =IF(G28/INDEX(Artigos!$G$2:$G$12,MATCH(B28,Artigos!$A$2:$A$12,0))<=1/3,"início",IF(G28/INDEX(Artigos!$G$2:$G$12,MATCH(B28,Artigos!$A$2:$A$12,0))<=2/3,"meio","fim")) -> meio | K28: Útil também para a seção de AI Assurance do artigo da TE-251.
A29: A3-08 | B29: 3 | C29: Sifakis, 2015 | D29: Argumento | E29: Por causa das anomalias temporais, garantir segurança para o pior tempo de execução (WCET) não garante segurança para tempos de execução menores. | F29: p. 5 | G29: 5 | H29: =IF(G29/INDEX(Artigos!$G$2:$G$12,MATCH(B29,Artigos!$A$2:$A$12,0))<=1/3,"início",IF(G29/INDEX(Artigos!$G$2:$G$12,MATCH(B29,Artigos!$A$2:$A$12,0))<=2/3,"meio","fim")) -> meio
A30: A3-09 | B30: 3 | C30: Sifakis, 2015 | D30: Resultado | E30: Expressividade universal na coordenação de componentes é obtida combinando interação multipartidária e prioridades, o que motivou o framework BIP. | F30: p. 6 | G30: 6 | H30: =IF(G30/INDEX(Artigos!$G$2:$G$12,MATCH(B30,Artigos!$A$2:$A$12,0))<=1/3,"início",IF(G30/INDEX(Artigos!$G$2:$G$12,MATCH(B30,Artigos!$A$2:$A$12,0))<=2/3,"meio","fim")) -> meio
A31: A3-10 | B31: 3 | C31: Sifakis, 2015 | D31: Conclusão | E31: Mesmo que os objetivos sejam atingidos, o projeto de sistemas nunca terá o grau de automação do projeto VLSI. | F31: p. 10 | G31: 10 | H31: =IF(G31/INDEX(Artigos!$G$2:$G$12,MATCH(B31,Artigos!$A$2:$A$12,0))<=1/3,"início",IF(G31/INDEX(Artigos!$G$2:$G$12,MATCH(B31,Artigos!$A$2:$A$12,0))<=2/3,"meio","fim")) -> fim
A32: A4-01 | B32: 4 | C32: Lozano et al., 2023 | D32: Contribuição | E32: Revisão abrangente dos trabalhos que usam hipervisores como base para sistemas embarcados críticos virtualizados, com comparação qualitativa; os autores dizem ser a primeira a reunir essa informação num só artigo. | F32: p. 1 | G32: 1 | H32: =IF(G32/INDEX(Artigos!$G$2:$G$12,MATCH(B32,Artigos!$A$2:$A$12,0))<=1/3,"início",IF(G32/INDEX(Artigos!$G$2:$G$12,MATCH(B32,Artigos!$A$2:$A$12,0))<=2/3,"meio","fim")) -> início
A33: A4-02 | B33: 4 | C33: Lozano et al., 2023 | D33: Contexto | E33: A adoção lenta de multicore em setores críticos se deve à interferência entre núcleos que disputam recursos compartilhados e ao impacto disso no WCET. | F33: p. 1 | G33: 1 | H33: =IF(G33/INDEX(Artigos!$G$2:$G$12,MATCH(B33,Artigos!$A$2:$A$12,0))<=1/3,"início",IF(G33/INDEX(Artigos!$G$2:$G$12,MATCH(B33,Artigos!$A$2:$A$12,0))<=2/3,"meio","fim")) -> início
A34: A4-03 | B34: 4 | C34: Lozano et al., 2023 | D34: Método | E34: A busca foi feita no IEEE Xplore e no Science Direct, complementada pelo Google Scholar; só entraram artigos de periódicos e anais, e livros foram descartados. | F34: p. 2 | G34: 2 | H34: =IF(G34/INDEX(Artigos!$G$2:$G$12,MATCH(B34,Artigos!$A$2:$A$12,0))<=1/3,"início",IF(G34/INDEX(Artigos!$G$2:$G$12,MATCH(B34,Artigos!$A$2:$A$12,0))<=2/3,"meio","fim")) -> início
A35: A4-04 | B35: 4 | C35: Lozano et al., 2023 | D35: Contexto | E35: Virtualização completa pode impor até 30% mais latência do que a execução direta no hardware. | F35: p. 5 | G35: 5 | H35: =IF(G35/INDEX(Artigos!$G$2:$G$12,MATCH(B35,Artigos!$A$2:$A$12,0))<=1/3,"início",IF(G35/INDEX(Artigos!$G$2:$G$12,MATCH(B35,Artigos!$A$2:$A$12,0))<=2/3,"meio","fim")) -> início
A36: A4-05 | B36: 4 | C36: Lozano et al., 2023 | D36: Contexto | E36: O ARINC 653 (primeiro rascunho em 1996) especifica particionamento temporal e espacial; sua interface APEX padroniza a ligação entre hipervisor/SO e aplicação. | F36: p. 6 | G36: 6 | H36: =IF(G36/INDEX(Artigos!$G$2:$G$12,MATCH(B36,Artigos!$A$2:$A$12,0))<=1/3,"início",IF(G36/INDEX(Artigos!$G$2:$G$12,MATCH(B36,Artigos!$A$2:$A$12,0))<=2/3,"meio","fim")) -> início
A37: A4-06 | B37: 4 | C37: Lozano et al., 2023 | D37: Contexto | E37: A eletrônica responde por cerca de 35% do custo de um veículo, com previsão de 50% até 2030; um carro atual tem mais de 150 ECUs. | F37: p. 7 | G37: 7 | H37: =IF(G37/INDEX(Artigos!$G$2:$G$12,MATCH(B37,Artigos!$A$2:$A$12,0))<=1/3,"início",IF(G37/INDEX(Artigos!$G$2:$G$12,MATCH(B37,Artigos!$A$2:$A$12,0))<=2/3,"meio","fim")) -> meio
A38: A4-07 | B38: 4 | C38: Lozano et al., 2023 | D38: Resultado | E38: 70% dos hipervisores analisados oferecem paravirtualização; só 25% são claramente do tipo 2. | F38: p. 14 | G38: 14 | H38: =IF(G38/INDEX(Artigos!$G$2:$G$12,MATCH(B38,Artigos!$A$2:$A$12,0))<=1/3,"início",IF(G38/INDEX(Artigos!$G$2:$G$12,MATCH(B38,Artigos!$A$2:$A$12,0))<=2/3,"meio","fim")) -> fim
A39: A4-08 | B39: 4 | C39: Lozano et al., 2023 | D39: Resultado | E39: Linux é o SO convidado mais comum (até 85% dos hipervisores); ARM é a arquitetura mais suportada (70%), seguida de x86 (50%), RISC-V (25%) e PowerPC (15%). | F39: p. 14–16 | G39: 14 | H39: =IF(G39/INDEX(Artigos!$G$2:$G$12,MATCH(B39,Artigos!$A$2:$A$12,0))<=1/3,"início",IF(G39/INDEX(Artigos!$G$2:$G$12,MATCH(B39,Artigos!$A$2:$A$12,0))<=2/3,"meio","fim")) -> fim | K39: Afirmação espalhada por três páginas, entre tabelas.
A40: A4-09 | B40: 4 | C40: Lozano et al., 2023 | D40: Resultado | E40: EUA, Alemanha e França respondem por 50% dos hipervisores analisados. | F40: p. 17 | G40: 17 | H40: =IF(G40/INDEX(Artigos!$G$2:$G$12,MATCH(B40,Artigos!$A$2:$A$12,0))<=1/3,"início",IF(G40/INDEX(Artigos!$G$2:$G$12,MATCH(B40,Artigos!$A$2:$A$12,0))<=2/3,"meio","fim")) -> fim
...

Sheet Artigos
A1: Nº | B1: Referência | C1: Título | D1: Autores | E1: Veículo | F1: Ano | G1: Páginas (PDF) | H1: DOI | I1: Nº de afirmações | J1: Aprovadas
A2: 1 | B2: Nimbekar et al., 2023 | C2: Reconfigurable VLSI Design Architecture for Deep Learning Established Forelimb and Hindlimb Gesture Recognition for Rehabilitation Application | D2: A. Nimbekar, Y. V. Sai Dinesh, A. Gautam, V. Hunsigida, A. R. Nali, A. Acharyya | E2: IEEE Access, vol. 11 | F2: 2023 | G2: 10 | H2: 10.1109/ACCESS.2023.3293422 | I2: =COUNTIF(Gabarito!B$2:B$1000,A2) -> 10 | J2: =COUNTIFS(Gabarito!B$2:B$1000,A2,Gabarito!I$2:I$1000,"Aprovada") -> 0
A3: 2 | B3: Breyer et al., 2022 | C3: A Comparison of SYCL, OpenCL, CUDA, and OpenMP for Massively Parallel Support Vector Machine Classification on Multi-Vendor Hardware | D3: M. Breyer, A. Van Craen, D. Pflüger | E3: IWOCL'22 (ACM) | F3: 2022 | G3: 12 | H3: 10.1145/3529538.3529980 | I3: =COUNTIF(Gabarito!B$2:B$1000,A3) -> 10 | J3: =COUNTIFS(Gabarito!B$2:B$1000,A3,Gabarito!I$2:I$1000,"Aprovada") -> 0
A4: 3 | B4: Sifakis, 2015 | C4: System Design Automation: Challenges and Limitations | D4: J. Sifakis | E4: Proceedings of the IEEE, vol. 103, n. 11 | F4: 2015 | G4: 11 | H4: 10.1109/JPROC.2015.2484060 | I4: =COUNTIF(Gabarito!B$2:B$1000,A4) -> 10 | J4: =COUNTIFS(Gabarito!B$2:B$1000,A4,Gabarito!I$2:I$1000,"Aprovada") -> 0
A5: 4 | B5: Lozano et al., 2023 | C5: A Comprehensive Survey on the Use of Hypervisors in Safety-Critical Systems | D5: S. Lozano, T. Lugo, J. Carretero | E5: IEEE Access, vol. 11 | F5: 2023 | G5: 20 | H5: 10.1109/ACCESS.2023.3264825 | I5: =COUNTIF(Gabarito!B$2:B$1000,A5) -> 10 | J5: =COUNTIFS(Gabarito!B$2:B$1000,A5,Gabarito!I$2:I$1000,"Aprovada") -> 0
A6: 5 | B6: Mzid, 2024 | C6: Real-time design patterns for the verification of safety-critical embedded systems in model-based approach | D6: R. Mzid | E6: The Journal of Supercomputing, vol. 80 | F6: 2024 | G6: 43 | H6: 10.1007/s11227-023-05866-0 | I6: =COUNTIF(Gabarito!B$2:B$1000,A6) -> 10 | J6: =COUNTIFS(Gabarito!B$2:B$1000,A6,Gabarito!I$2:I$1000,"Aprovada") -> 0
A7: 6 | B7: Young-S. et al., 2023 | C7: OpenMP Fortran programs for solving the time-dependent dipolar Gross-Pitaevskii equation | D7: L. E. Young-S., P. Muruganandam, A. Balaž, S. K. Adhikari | E7: Computer Physics Communications, vol. 286 | F7: 2023 | G7: 2 | H7: 10.1016/j.cpc.2023.108669 | I7: =COUNTIF(Gabarito!B$2:B$1000,A7) -> 6 | J7: =COUNTIFS(Gabarito!B$2:B$1000,A7,Gabarito!I$2:I$1000,"Aprovada") -> 0
A8: 7 | B8: Leppänen et al., 2023 | C8: Efficient OpenCL system integration of non-blocking FPGA accelerators | D8: T. Leppänen, A. Lotvonen, P. Mousouliotis, J. Multanen, G. Keramidas, P. Jääskeläinen | E8: Microprocessors and Microsystems, vol. 97 | F8: 2023 | G8: 11 | H8: 10.1016/j.micpro.2023.104772 | I8: =COUNTIF(Gabarito!B$2:B$1000,A8) -> 10 | J8: =COUNTIFS(Gabarito!B$2:B$1000,A8,Gabarito!I$2:I$1000,"Aprovada") -> 0
A9: 8 | B9: Yoshida et al., 2024 | C9: Analyzing the impact of CUDA versions on GPU applications | D9: K. Yoshida, S. Miwa, H. Yamaki, H. Honda | E9: Parallel Computing, vol. 120 | F9: 2024 | G9: 10 | H9: 10.1016/j.parco.2024.103081 | I9: =COUNTIF(Gabarito!B$2:B$1000,A9) -> 11 | J9: =COUNTIFS(Gabarito!B$2:B$1000,A9,Gabarito!I$2:I$1000,"Aprovada") -> 0
A10: 9 | B10: FAA, 2024 | C10: Advisory Circular AC 20-193: Use of Multi-Core Processors | D10: Federal Aviation Administration (AIR-622) | E10: FAA Advisory Circular | F10: 2024 | G10: 18 | H10: — | I10: =COUNTIF(Gabarito!B$2:B$1000,A10) -> 11 | J10: =COUNTIFS(Gabarito!B$2:B$1000,A10,Gabarito!I$2:I$1000,"Aprovada") -> 0
A11: 10 | B11: Peralta Quesada et al., 2023 | C11: Evaluation of SYCL's Suitability for High-Performance Critical Systems | D11: C. Peralta Quesada, M. M. Trompouki, L. Kosmidis | E11: IWOCL'23 (ACM) | F11: 2023 | G11: 11 | H11: 10.1145/3585341.3585378 | I11: =COUNTIF(Gabarito!B$2:B$1000,A11) -> 11 | J11: =COUNTIFS(Gabarito!B$2:B$1000,A11,Gabarito!I$2:I$1000,"Aprovada") -> 0
A12: 11 | B12: Loubach et al., 2019 | C12: Considerations on Domain-Specific Architectures Applicability in Future Avionics Systems (slides) | D12: D. S. Loubach, J. C. Marques, A. M. da Cunha | E12: 10th Aerospace Technology Congress (FT2019), Stockholm | F12: 2019 | G12: 23 | H12: — | I12: =COUNTIF(Gabarito!B$2:B$1000,A12) -> 10 | J12: =COUNTIFS(Gabarito!B$2:B$1000,A12,Gabarito!I$2:I$1000,"Aprovada") -> 0
